<?xml version="1.0" ?>
<!-- =================================================================================== -->
<!-- |    This document was autogenerated by xacro from src/kuka_simulators/kuka_lbr_iisy_support/urdf/lbr_iisy11_r1300.urdf.xacro | -->
<!-- |    EDITING THIS FILE BY HAND IS NOT RECOMMENDED                                 | -->
<!-- =================================================================================== -->
<robot name="LBRiisy11R1300">
  <!-- colours based on RAL values given in "FAQ - Colours of robot and robot
       controller", version "KUKA.Tifs | 2010-01-21 |YM| DefaultColorsRobotAndController.doc",
       downloaded 2015-07-18 from
       http://www.kuka.be/main/cservice/faqs/hardware/DefaultColorsRobotAndController.pdf

       all RAL colours converted using http://www.visual-graphics.de/en/customer-care/ral-colours
  -->
  <!-- Read parameters from eci_config  -->
  <!-- <xacro:property name="eci_config" value="$(find kuka_rox_hw_interface)/config/eci_config.yaml" /> -->
  <!-- <xacro:property name="eci_config_dict" value="${xacro.load_yaml(eci_config)}"/> -->
  <!-- <xacro:property name="control_mode" value="${eci_config_dict['robot_manager']['ros__parameters']['control_mode']}" /> -->
  <!-- <xacro:property name="client_ip" value="${eci_config_dict['robot_manager']['ros__parameters']['client_ip']}" /> -->
  <!-- <xacro:property name="controller_ip" value="${eci_config_dict['robot_manager']['ros__parameters']['controller_ip']}" /> -->
  <!-- Read QoS profile parameters  -->
  <!-- <xacro:property name="qos_config" value="$(find kuka_rox_hw_interface)/config/qos_profiles.yaml" /> -->
  <!-- <xacro:property name="qos_config_dict" value="${xacro.load_yaml(qos_config)}"/> -->
  <!-- <xacro:property name="consequent_lost_packets" value="${qos_config_dict['rt_packet_loss_profile']['consequent_lost_packets']}" /> -->
  <!-- <xacro:property name="lost_packets_in_timeframe" value="${qos_config_dict['rt_packet_loss_profile']['lost_packets_in_timeframe']}" />
<xacro:property name="timeframe_ms" value="${qos_config_dict['rt_packet_loss_profile']['timeframe_ms']}" /> -->
  <ros2_control name="LBRiisy11R1300" type="system">
    <!-- <hardware>
      <plugin>kuka_rox::KukaRoXHardwareInterface</plugin>
      <param name="client_ip">127.0.0.1</param>
      <param name="controller_ip">127.0.0.1</param>
      <param name="control_mode">1</param>
      <param name="consequent_lost_packets">1</param>
      <param name="lost_packets_in_timeframe">1</param>
      <param name="timeframe_ms">1</param>
    </hardware> -->
    <!-- define joints and command/state interfaces for each joint -->
    <joint name="joint_a1">
      <command_interface name="position"/>
      <command_interface name="stiffness"/>
      <command_interface name="damping"/>
      <command_interface name="effort"/>
      <state_interface name="position"/>
      <state_interface name="effort"/>
    </joint>
    <joint name="joint_a2">
      <command_interface name="position"/>
      <command_interface name="stiffness"/>
      <command_interface name="damping"/>
      <command_interface name="effort"/>
      <state_interface name="position"/>
      <state_interface name="effort"/>
    </joint>
    <joint name="joint_a3">
      <command_interface name="position"/>
      <command_interface name="stiffness"/>
      <command_interface name="damping"/>
      <command_interface name="effort"/>
      <state_interface name="position"/>
      <state_interface name="effort"/>
    </joint>
    <joint name="joint_a4">
      <command_interface name="position"/>
      <command_interface name="stiffness"/>
      <command_interface name="damping"/>
      <command_interface name="effort"/>
      <state_interface name="position"/>
      <state_interface name="effort"/>
    </joint>
    <joint name="joint_a5">
      <command_interface name="position"/>
      <command_interface name="stiffness"/>
      <command_interface name="damping"/>
      <command_interface name="effort"/>
      <state_interface name="position"/>
      <state_interface name="effort"/>
    </joint>
    <joint name="joint_a6">
      <command_interface name="position"/>
      <command_interface name="stiffness"/>
      <command_interface name="damping"/>
      <command_interface name="effort"/>
      <state_interface name="position"/>
      <state_interface name="effort"/>
    </joint>
  </ros2_control>
  <!-- links - main serial chain -->
  <!-- links - root element cannot have inertia, therefore a dummy base_link is needed -->
  <link name="base_link"/>
  <link name="base_link_inertia">
    <collision>
      <geometry>
        <mesh filename="package://iisy11_model/meshes/LBRiisy11R1300/collision/base_link.stl"/>
      </geometry>
      <origin rpy="-0.0 0.0 -0.0" xyz="0.0 0.0 0.0"/>
    </collision>
    <inertial>
      <inertia ixx="0.05163236" ixy="0.0" ixz="0.0" iyy="0.03961305" iyz="0.0" izz="0.05515706"/>
      <mass value="8.865E0"/>
      <origin rpy="-0.0 0.0 -0.0" xyz="0.0 0.0 0.0"/>
    </inertial>
    <visual>
      <geometry>
        <mesh filename="package://iisy11_model/meshes/LBRiisy11R1300/visual/base_link.stl"/>
      </geometry>
      <origin rpy="-0.0 0.0 -0.0" xyz="0.0 0.0 0.0"/>
      <material name="">
        <color rgba="0.9450980392156862 0.9254901960784314 1.0 1.0"/>
      </material>
    </visual>
  </link>
  <link name="link_1">
    <collision>
      <geometry>
        <mesh filename="package://iisy11_model/meshes/LBRiisy11R1300/collision/link_1.stl"/>
      </geometry>
      <origin rpy="-0.0 0.0 -0.0" xyz="0.0 0.0 0.0"/>
    </collision>
    <inertial>
      <inertia ixx="0.62408426" ixy="0.0" ixz="0.0" iyy="0.03943643" iyz="0.0" izz="0.63132936"/>
      <mass value="9.87E0"/>
      <origin rpy="-0.0 0.0 -0.0" xyz="0.0 0.0 0.0"/>
    </inertial>
    <visual>
      <geometry>
        <mesh filename="package://iisy11_model/meshes/LBRiisy11R1300/visual/link_1.stl"/>
      </geometry>
      <origin rpy="-0.0 0.0 -0.0" xyz="0.0 0.0 0.0"/>
      <material name="">
        <color rgba="0.9450980392156862 0.9254901960784314 1.0 1.0"/>
      </material>
    </visual>
  </link>
  <link name="link_2">
    <collision>
      <geometry>
        <mesh filename="package://iisy11_model/meshes/LBRiisy11R1300/collision/link_2.stl"/>
      </geometry>
      <origin rpy="-0.0 0.0 -0.0" xyz="0.0 0.0 0.0"/>
    </collision>
    <inertial>
      <inertia ixx="0.01739898" ixy="0.0" ixz="0.0" iyy="0.03354988" iyz="0.0" izz="0.0366683"/>
      <mass value="1.0139E1"/>
      <origin rpy="-0.0 0.0 -0.0" xyz="0.0 0.0 0.0"/>
    </inertial>
    <visual>
      <geometry>
        <mesh filename="package://iisy11_model/meshes/LBRiisy11R1300/visual/link_2.stl"/>
      </geometry>
      <origin rpy="-0.0 0.0 -0.0" xyz="0.0 0.0 0.0"/>
      <material name="">
        <color rgba="0.9450980392156862 0.9254901960784314 1.0 1.0"/>
      </material>
    </visual>
  </link>
  <link name="link_3">
    <collision>
      <geometry>
        <mesh filename="package://iisy11_model/meshes/LBRiisy11R1300/collision/link_3.stl"/>
      </geometry>
      <origin rpy="-0.0 0.0 -0.0" xyz="0.0 0.0 0.0"/>
    </collision>
    <inertial>
      <inertia ixx="0.02748508" ixy="0.0" ixz="0.0" iyy="0.16186323" iyz="0.0" izz="0.1694282"/>
      <mass value="7.5014E0"/>
      <origin rpy="-0.0 0.0 -0.0" xyz="0.0 0.0 0.0"/>
    </inertial>
    <visual>
      <geometry>
        <mesh filename="package://kuka_lbr_iisy_support/meshes/LBRiisy11R1300/visual/link_3.stl"/>
      </geometry>
      <origin rpy="-0.0 0.0 -0.0" xyz="0.0 0.0 0.0"/>
      <material name="">
        <color rgba="0.9450980392156862 0.9254901960784314 1.0 1.0"/>
      </material>
    </visual>
  </link>
  <link name="link_4">
    <collision>
      <geometry>
        <mesh filename="package://kuka_lbr_iisy_support/meshes/LBRiisy11R1300/collision/link_4.stl"/>
      </geometry>
      <origin rpy="-0.0 0.0 -0.0" xyz="0.0 0.0 0.0"/>
    </collision>
    <inertial>
      <inertia ixx="0.00716767" ixy="0.0" ixz="0.0" iyy="0.00536601" iyz="0.0" izz="0.0089832"/>
      <mass value="6.9744E0"/>
      <origin rpy="-0.0 0.0 -0.0" xyz="0.0 0.0 0.0"/>
    </inertial>
    <visual>
      <geometry>
        <mesh filename="package://kuka_lbr_iisy_support/meshes/LBRiisy11R1300/visual/link_4.stl"/>
      </geometry>
      <origin rpy="-0.0 0.0 -0.0" xyz="0.0 0.0 0.0"/>
      <material name="">
        <color rgba="0.9450980392156862 0.9254901960784314 1.0 1.0"/>
      </material>
    </visual>
  </link>
  <link name="link_5">
    <collision>
      <geometry>
        <mesh filename="package://kuka_lbr_iisy_support/meshes/LBRiisy11R1300/collision/link_5.stl"/>
      </geometry>
      <origin rpy="-0.0 0.0 -0.0" xyz="0.0 0.0 0.0"/>
    </collision>
    <inertial>
      <inertia ixx="0.00396428" ixy="0.0" ixz="0.0" iyy="0.00292738" iyz="0.0" izz="0.00410763"/>
      <mass value="2.509E0"/>
      <origin rpy="-0.0 0.0 -0.0" xyz="0.0 0.0 0.0"/>
    </inertial>
    <visual>
      <geometry>
        <mesh filename="package://kuka_lbr_iisy_support/meshes/LBRiisy11R1300/visual/link_5.stl"/>
      </geometry>
      <origin rpy="-0.0 0.0 -0.0" xyz="0.0 0.0 0.0"/>
      <material name="">
        <color rgba="0.9450980392156862 0.9254901960784314 1.0 1.0"/>
      </material>
    </visual>
  </link>
  <link name="link_6">
    <collision>
      <geometry>
        <mesh filename="package://kuka_lbr_iisy_support/meshes/LBRiisy11R1300/collision/link_6.stl"/>
      </geometry>
      <origin rpy="-0.0 0.0 -0.0" xyz="0.0 0.0 0.0"/>
    </collision>
    <inertial>
      <inertia ixx="0.00396428" ixy="0.0" ixz="0.0" iyy="0.00292738" iyz="0.0" izz="0.00410763"/>
      <mass value="1.527E0"/>
      <origin rpy="-0.0 0.0 -0.0" xyz="0.0 0.0 0.0"/>
    </inertial>
    <visual>
      <geometry>
        <mesh filename="package://kuka_lbr_iisy_support/meshes/LBRiisy11R1300/visual/link_6.stl"/>
      </geometry>
      <origin rpy="-0.0 0.0 -0.0" xyz="0.0 0.0 0.0"/>
      <material name="">
        <color rgba="0.9450980392156862 0.9254901960784314 1.0 1.0"/>
      </material>
    </visual>
  </link>
  <!-- joints - main serial chain -->
  <joint name="base_link-base_link_inertia" type="fixed">
    <parent link="base_link"/>
    <child link="base_link_inertia"/>
    <origin rpy="0 0 0" xyz="0 0 0"/>
  </joint>
  <joint name="joint_a1" type="revolute">
    <axis xyz="0.0 0.0 1.0"/>
    <child link="link_1"/>
    <limit effort="405.840000" lower="-3.2288591161895095E0" upper="3.2288591161895095E0" velocity="3.490656"/>
    <origin rpy="-3.141592653589793 0.0 -0.0" xyz="0.0 0.0 0.0"/>
    <parent link="base_link_inertia"/>
  </joint>
  <joint name="joint_a2" type="revolute">
    <axis xyz="0.0 0.0 1.0"/>
    <child link="link_2"/>
    <limit effort="366.247685" lower="-4.014257279586958E0" upper="8.726646259971648E-1" velocity="3.490656"/>
    <origin rpy="1.5707963267948966 0.0 -0.0" xyz="0.0 0.0 -0.3"/>
    <parent link="link_1"/>
  </joint>
  <joint name="joint_a3" type="revolute">
    <axis xyz="0.0 0.0 1.0"/>
    <child link="link_3"/>
    <limit effort="147.189440" lower="-2.6179938779914944E0" upper="2.6179938779914944E0" velocity="3.490656"/>
    <origin rpy="0.0 0.0 -1.5707963267948966" xyz="0.59 0.0 0.0"/>
    <parent link="link_2"/>
  </joint>
  <joint name="joint_a4" type="revolute">
    <axis xyz="0.0 0.0 1.0"/>
    <child link="link_4"/>
    <limit effort="65.482547" lower="-3.141592653589793E0" upper="3.141592653589793E0" velocity="4.014255"/>
    <origin rpy="1.5707963267948966 0.0 -0.0" xyz="0.0 0.0 0.0"/>
    <parent link="link_3"/>
  </joint>
  <joint name="joint_a5" type="revolute">
    <axis xyz="0.0 0.0 1.0"/>
    <child link="link_5"/>
    <limit effort="64.657647" lower="-1.9198621771937625E0" upper="1.9198621771937625E0" velocity="4.537856"/>
    <origin rpy="-1.5707963267948966 0.0 -0.0" xyz="0.0 0.0 -0.532"/>
    <parent link="link_4"/>
  </joint>
  <joint name="joint_a6" type="revolute">
    <axis xyz="0.0 0.0 1.0"/>
    <child link="link_6"/>
    <limit effort="15.720233" lower="-3.839724354387525E0" upper="3.839724354387525E0" velocity="7.504909"/>
    <origin rpy="1.5707963267948966 0.0 -0.0" xyz="0.0 0.0 0.0"/>
    <parent link="link_5"/>
  </joint>
  <!-- ROS-Industrial 'base' frame - equivalent of 'KUKA ROBROOT'-->
  <link name="base"/>
  <joint name="base_link-base" type="fixed">
    <origin rpy="0 0 0" xyz="0 0 0"/>
    <parent link="base_link"/>
    <child link="base"/>
  </joint>
  <!-- ROS-Industrial 'flange' frame - attachment point for EEF models -->
  <link name="flange"/>
  <joint name="link6-flange" type="fixed">
    <child link="flange"/>
    <origin rpy="0 3.141592653589793 -0.0" xyz="0.0 0.0 -0.178"/>
    <parent link="link_6"/>
  </joint>
  <!-- ROS-Industrial 'tool0' frame - all-zeros tool frame -->
  <link name="tool0"/>
  <joint name="link6-tool0" type="fixed">
    <child link="tool0"/>
    <origin rpy="0 3.141592653589793 -0.0" xyz="0.0 0.0 -0.178"/>
    <parent link="link_6"/>
  </joint>
</robot>
